<?xml version="1.0" ?>
<robot name="abb_irb6660">
<!-- link list -->
  <link name="base_link">
    <collision name="collision">
      <geometry>
        <mesh filename="package://abb_irb6660_support/meshes/collision/base_link.stl" scale="0.001 0.001 0.001"/>
      </geometry>
    </collision>
    <visual name="visual">
      <geometry>
        <mesh filename="package://abb_irb6660_support/meshes/visual/base_link.dae" scale="0.001 0.001 0.001"/>
      </geometry>
      <material name="orange">
        <color rgba="1 0.5 0 1"/>
      </material>
    </visual>
  </link>
  <link name="link_1">
    <collision name="collision">
      <geometry>
        <mesh filename="package://abb_irb6660_support/meshes/collision/link_1.stl" scale="0.001 0.001 0.001"/>
      </geometry>
    </collision>
    <visual name="visual">
      <geometry>
        <mesh filename="package://abb_irb6660_support/meshes/visual/link_1.dae" scale="0.001 0.001 0.001"/>
      </geometry>
      <material name="orange"/>
    </visual>
  </link>
  <link name="link_2">
    <collision name="collision">
      <geometry>
        <mesh filename="package://abb_irb6660_support/meshes/collision/link_2.stl" scale="0.001 0.001 0.001"/>
      </geometry>
    </collision>
    <visual name="visual">
      <geometry>
        <mesh filename="package://abb_irb6660_support/meshes/visual/link_2.dae" scale="0.001 0.001 0.001"/>
      </geometry>
      <material name="orange"/>
    </visual>
  </link>
  <link name="link_3">
    <collision name="collision">
      <geometry>
        <mesh filename="package://abb_irb6660_support/meshes/collision/link_3.stl" scale="0.001 0.001 0.001"/>
      </geometry>
    </collision>
    <visual name="visual">
      <geometry>
        <mesh filename="package://abb_irb6660_support/meshes/visual/link_3.dae" scale="0.001 0.001 0.001"/>
      </geometry>
      <material name="orange"/>
    </visual>
  </link>
  <link name="link_4">
    <collision name="collision">
      <geometry>
        <mesh filename="package://abb_irb6660_support/meshes/collision/link_4.stl" scale="0.001 0.001 0.001"/>
      </geometry>
    </collision>
    <visual name="visual">
      <geometry>
        <mesh filename="package://abb_irb6660_support/meshes/visual/link_4.dae" scale="0.001 0.001 0.001"/>
      </geometry>
      <material name="orange"/>
    </visual>
  </link>
  <link name="link_5">
    <collision name="collision">
      <geometry>
        <mesh filename="package://abb_irb6660_support/meshes/collision/link_5.stl" scale="0.001 0.001 0.001"/>
      </geometry>
    </collision>
    <visual name="visual">
      <geometry>
        <mesh filename="package://abb_irb6660_support/meshes/visual/link_5.dae" scale="0.001 0.001 0.001"/>
      </geometry>
      <material name="orange"/>
    </visual>
  </link>
  <link name="link_6">
    <collision name="collision">
      <geometry>
        <mesh filename="package://abb_irb6660_support/meshes/collision/link_6.stl" scale="0.001 0.001 0.001"/>
      </geometry>
    </collision>
    <visual name="visual">
      <geometry>
        <mesh filename="package://abb_irb6660_support/meshes/visual/link_6.dae" scale="0.001 0.001 0.001"/>
      </geometry>
      <material name="orange"/>
    </visual>
  </link>
  <!-- joint list -->
  <joint name="joint_1" type="revolute">
    <origin rpy="0 0 0" xyz="0 0 0.214"/>
    <axis xyz="0 0 1"/>
    <parent link="base_link"/>
    <child link="link_1"/>
    <limit effort="0" lower="-3.142" upper="3.142" velocity="2.269"/>
  </joint>
  <joint name="joint_2" type="revolute">
    <origin rpy="0 0 0" xyz="0.3 0 0.600"/>
    <axis xyz="0 1 0"/>
    <parent link="link_1"/>
    <child link="link_2"/>
    <limit effort="0" lower="-0.733" upper="1.484" velocity="2.269"/>
  </joint>
  <joint name="joint_3" type="revolute">
    <origin rpy="0 0 0" xyz="0 0 0.7"/>
    <axis xyz="0 1 0"/>
    <parent link="link_2"/>
    <child link="link_3"/>
    <limit effort="0" lower="-0.349" upper="2.094" velocity="2.269"/>
  </joint>
  <joint name="joint_4" type="revolute">
    <origin rpy="0 0 0" xyz="0 0 0.28"/>
    <axis xyz="1 0 0"/>
    <parent link="link_3"/>
    <child link="link_4"/>
    <limit effort="0" lower="-5.236" upper="5.236" velocity="2.618"/>
  </joint>
  <joint name="joint_5" type="revolute">
    <origin rpy="0 0 0" xyz="0.893 0 0 "/>
    <axis xyz="0 1 0"/>
    <parent link="link_4"/>
    <child link="link_5"/>
    <limit effort="0" lower="-2.094" upper="2.094" velocity="2.0944"/>
  </joint>
  <joint name="joint_6" type="revolute">
    <origin rpy="0 0 0" xyz="0.154 0 0 "/>
    <axis xyz="1 0 0"/>
    <parent link="link_5"/>
    <child link="link_6"/>
    <limit effort="0" lower="-6.283" upper="6.283" velocity="3.3161"/>
  </joint>
  <!-- ROS base_link to ABB World Coordinates transform -->
  <!-- <link name="base"/>
  <joint name="base_link-base" type="fixed">
    <origin rpy="0 0 0" xyz="0 0 0"/>
    <parent link="base_link"/>
    <child link="base"/>
  </joint> -->
</robot>

